<?xml version="1.0" ?>
<robot name="mybot" xmlns:xacro="http://www.ros.org/wiki/xacro">

<xacro:include filename="$(find mybot_description)/urdf/materials.xacro" />
<xacro:include filename="$(find mybot_description)/urdf/mybot.trans" />
<xacro:include filename="$(find mybot_description)/urdf/mybot.gazebo" />
<!-- BASE LINK -->

    <link name="base_link">

    </link>

    <!-- BASE_FOOTPRINT LINK -->

    <joint name="base_footprint_joint" type="fixed">
        <parent link="base_link"/>
        <child link="base_footprint"/>
        <origin xyz="0 0 0" rpy="0 0 0"/>
    </joint>

    <link name="base_footprint">
    </link>





<joint name="chassis_joint" type="fixed">
        <parent link="base_link"/>
        <child link="chassis"/>
        <origin xyz="0.25839885705674864 2.0307340956054744e-17 0.03695407073761257"/>
    </joint>
    
<link name="chassis">
  <inertial>
    <origin xyz="0.25839885705674864 2.0307340956054744e-17 0.03695407073761257" rpy="0 0 0"/>
    <mass value="19.347767490394116"/>
    <inertia ixx="0.297302" iyy="0.756999" izz="0.99265" ixy="-0.0" iyz="0.0" ixz="-0.055153"/>
  </inertial>
  <visual>
    <origin xyz="0 0 0" rpy="0 0 0"/>
    <geometry>
      <mesh filename="package://mybot_description/meshes/base_link.stl" scale="0.001 0.001 0.001"/>
    </geometry>
    <material name="silver"/>
  </visual>
  <collision>
    <origin xyz="0 0 0" rpy="0 0 0"/>
    <geometry>
      <mesh filename="package://mybot_description/meshes/base_link.stl" scale="0.001 0.001 0.001"/>
    </geometry>
  </collision>
</link>

<link name="left_wheel_l">
  <inertial>
    <origin xyz="-2.487255623929074e-07 0.08085491880765591 -7.622460057191507e-06" rpy="0 0 0"/>
    <mass value="0.8909473644045303"/>
    <inertia ixx="0.001474" iyy="0.002513" izz="0.001474" ixy="-0.0" iyz="-0.0" ixz="0.0"/>
  </inertial>
  <visual>
    <origin xyz="-0.0 -0.146 -0.0" rpy="0 0 0"/>
    <geometry>
      <mesh filename="package://mybot_description/meshes/left_wheel_1.stl" scale="0.001 0.001 0.001"/>
    </geometry>
    <material name="silver"/>
  </visual>
  <collision>
    <origin xyz="-0.0 -0.146 -0.0" rpy="0 0 0"/>
    <geometry>
      <mesh filename="package://mybot_description/meshes/left_wheel_1.stl" scale="0.001 0.001 0.001"/>
    </geometry>
  </collision>
</link>

<link name="right_wheel_l">
  <inertial>
    <origin xyz="-2.4383168080722895e-07 -0.08085408001707872 -6.934637793741147e-06" rpy="0 0 0"/>
    <mass value="0.8909661209663764"/>
    <inertia ixx="0.001474" iyy="0.002514" izz="0.001474" ixy="0.0" iyz="0.0" ixz="0.0"/>
  </inertial>
  <visual>
    <origin xyz="-0.0 0.146 -0.0" rpy="0 0 0"/>
    <geometry>
      <mesh filename="package://mybot_description/meshes/right_wheel_1.stl" scale="0.001 0.001 0.001"/>
    </geometry>
    <material name="silver"/>
  </visual>
  <collision>
    <origin xyz="-0.0 0.146 -0.0" rpy="0 0 0"/>
    <geometry>
      <mesh filename="package://mybot_description/meshes/right_wheel_1.stl" scale="0.001 0.001 0.001"/>
    </geometry>
  </collision>
</link>

<link name="camera">
  <inertial>
    <origin xyz="0.010000000000000009 0.0 0.0" rpy="0 0 0"/>
    <mass value="0.1256"/>
    <inertia ixx="2.1e-05" iyy="8e-06" izz="2.1e-05" ixy="0.0" iyz="0.0" ixz="0.0"/>
  </inertial>
  <visual>
    <origin xyz="-0.5185 -0.0 -0.15" rpy="0 0 0"/>
    <geometry>
      <mesh filename="package://mybot_description/meshes/camera_1.stl" scale="0.001 0.001 0.001"/>
    </geometry>
    <material name="silver"/>
  </visual>
  <collision>
    <origin xyz="-0.5185 -0.0 -0.15" rpy="0 0 0"/>
    <geometry>
      <mesh filename="package://mybot_description/meshes/camera_1.stl" scale="0.001 0.001 0.001"/>
    </geometry>
  </collision>
</link>

<link name="caster_wheel">
  <inertial>
    <origin xyz="-5.551115123125783e-17 0.0 -0.03799999999999998" rpy="0 0 0"/>
    <mass value="0.29451054679421534"/>
    <inertia ixx="0.000153" iyy="0.000153" izz="2.3e-05" ixy="-0.0" iyz="-0.0" ixz="-0.0"/>
  </inertial>
  <visual>
    <origin xyz="-0.475 -0.0 0.003" rpy="0 0 0"/>
    <geometry>
      <mesh filename="package://mybot_description/meshes/caster_wheel_1.stl" scale="0.001 0.001 0.001"/>
    </geometry>
    <material name="silver"/>
  </visual>
  <collision>
    <origin xyz="-0.475 -0.0 0.003" rpy="0 0 0"/>
    <geometry>
      <mesh filename="package://mybot_description/meshes/caster_wheel_1.stl" scale="0.001 0.001 0.001"/>
    </geometry>
  </collision>
</link>

<link name="laser">
  <inertial>
    <origin xyz="-0.006766530116657676 9.192611113994242e-05 0.013668127732840374" rpy="0 0 0"/>
    <mass value="1.3392997077576572"/>
    <inertia ixx="0.000619" iyy="0.000967" izz="0.001105" ixy="-1e-06" iyz="3e-06" ixz="-0.000159"/>
  </inertial>
  <visual>
    <origin xyz="-0.498 -0.0 -0.169" rpy="0 0 0"/>
    <geometry>
      <mesh filename="package://mybot_description/meshes/laser_1.stl" scale="0.001 0.001 0.001"/>
    </geometry>
    <material name="silver"/>
  </visual>
  <collision>
    <origin xyz="-0.498 -0.0 -0.169" rpy="0 0 0"/>
    <geometry>
      <mesh filename="package://mybot_description/meshes/laser_1.stl" scale="0.001 0.001 0.001"/>
    </geometry>
  </collision>
</link>

<joint name="left_wheel" type="continuous">
  <origin xyz="0.0 0.146 0.0" rpy="0 0 0"/>
  <parent link="base_link"/>
  <child link="left_wheel_l"/>
  <axis xyz="0.0 1.0 0.0"/>
</joint>

<joint name="right_wheel" type="continuous">
  <origin xyz="0.0 -0.146 0.0" rpy="0 0 0"/>
  <parent link="base_link"/>
  <child link="right_wheel_l"/>
  <axis xyz="0.0 1.0 0.0"/>
</joint>

<joint name="camera_j" type="fixed">
  <origin xyz="0.5185 0.0 0.15" rpy="0 0 0"/>
  <parent link="base_link"/>
  <child link="camera"/>
</joint>

<joint name="caster_wheel_j" type="fixed">
  <origin xyz="0.475 0.0 -0.003" rpy="0 0 0"/>
  <parent link="base_link"/>
  <child link="caster_wheel"/>
</joint>

<joint name="laser_j" type="fixed">
  <origin xyz="0.498 0.0 0.169" rpy="0 0 0"/>
  <parent link="base_link"/>
  <child link="laser"/>
</joint>

</robot>
